Workbook

Sheet Tulokset
A1: MM 2026 - tulosten syöttö | L1: Lohkojen ja finaalivaiheen tulokset
A2: Syötä toteutuneet maalit sarakkeisiin G ja I. Jätä kesken olevat/pelaamattomat ottelut tyhjiksi. | L2: Syötä lohkojen lopullinen järjestys sekä finaalijoukkueet. Lohko- ja finaalipisteet päivittyvät Pisteet-välilehdelle.
A4: Otteluiden tulokset
A5: Nro | B5: Pvm | C5: Lohko | D5: Joukkue 1 | E5: - | F5: Joukkue 2 | G5: Maalit 1 | H5: - | I5: Maalit 2 | L5: Sijoitus | M5: Lohko A | N5: Lohko B | O5: Lohko C | P5: Lohko D | Q5: Lohko E | R5: Lohko F
A6: 1 | B6: 11.6. klo 22 | C6: A | D6: Meksiko | E6: - | F6: Etelä-Afrikka | H6: - | L6: 1
A7: 2 | B7: 12.6. klo 05 | C7: A | D7: Etelä-Korea | E7: - | F7: Tshekki | H7: - | L7: 2
A8: 3 | B8: 12.6. klo 22 | C8: B | D8: Kanada | E8: - | F8: Bosnia ja Hertsegovina | H8: - | L8: 3
A9: 4 | B9: 13.6. klo 04 | C9: D | D9: USA | E9: - | F9: Paraguay | H9: - | L9: 4
A10: 5 | B10: 14.6. klo 04 | C10: C | D10: Haiti | E10: - | F10: Skotlanti | H10: -
A11: 6 | B11: 14.6. klo 07 | C11: D | D11: Australia | E11: - | F11: Turkki | H11: - | L11: Sijoitus | M11: Lohko G | N11: Lohko H | O11: Lohko I | P11: Lohko J | Q11: Lohko K | R11: Lohko L
A12: 7 | B12: 14.6. klo 01 | C12: C | D12: Brasilia | E12: - | F12: Marokko | H12: - | L12: 1
A13: 8 | B13: 13.6. klo 22 | C13: B | D13: Qatar | E13: - | F13: Sveitsi | H13: - | L13: 2
A14: 9 | B14: 15.6. klo 02 | C14: E | D14: Norsunluurannikko | E14: - | F14: Ecuador | H14: - | L14: 3
A15: 10 | B15: 14.6. klo 20 | C15: E | D15: Saksa | E15: - | F15: Curaçao | H15: - | L15: 4
A16: 11 | B16: 14.6. klo 23 | C16: F | D16: Hollanti | E16: - | F16: Japani | H16: -
A17: 12 | B17: 15.6. klo 05 | C17: F | D17: Ruotsi | E17: - | F17: Tunisia | H17: -
A18: 13 | B18: 16.6. klo 01 | C18: H | D18: Saudi-Arabia | E18: - | F18: Uruguay | H18: - | L18: Finaalijoukkueet ja sijat 3-4
A19: 14 | B19: 15.6. klo 19 | C19: H | D19: Espanja | E19: - | F19: Kap Verde | H19: -
A20: 15 | B20: 16.6. klo 04 | C20: G | D20: Iran | E20: - | F20: Uusi-Seelanti | H20: - | L20: Finaalijoukkue 1
A21: 16 | B21: 15.6. klo 22 | C21: G | D21: Belgia | E21: - | F21: Egypti | H21: - | L21: Finaalijoukkue 2
A22: 17 | B22: 16.6. klo 22 | C22: I | D22: Ranska | E22: - | F22: Senegal | H22: -
A23: 18 | B23: 17.6. klo 01 | C23: I | D23: Irak | E23: - | F23: Norja | H23: - | L23: Sijat 3-4, joukkue 1
A24: 19 | B24: 17.6. klo 04 | C24: J | D24: Argentiina | E24: - | F24: Algeria | H24: - | L24: Sijat 3-4, joukkue 2
A25: 20 | B25: 17.6. klo 07 | C25: J | D25: Itävalta | E25: - | F25: Jordania | H25: -
A26: 21 | B26: 18.6. klo 02 | C26: L | D26: Ghana | E26: - | F26: Panama | H26: -
A27: 22 | B27: 17.6. klo 23 | C27: L | D27: Englanti | E27: - | F27: Kroatia | H27: -
A28: 23 | B28: 17.6. klo 20 | C28: K | D28: Portugali | E28: - | F28: Kongon DR | H28: -
A29: 24 | B29: 18.6. klo 05 | C29: K | D29: Uzbekistan | E29: - | F29: Kolumbia | H29: -
A30: 25 | B30: 18.6. klo 19 | C30: A | D30: Tshekki | E30: - | F30: Etelä-Afrikka | H30: -
A31: 26 | B31: 18.6. klo 22 | C31: B | D31: Sveitsi | E31: - | F31: Bosnia ja Hertsegovina | H31: -
A32: 27 | B32: 19.6. klo 01 | C32: B | D32: Kanada | E32: - | F32: Qatar | H32: -
A33: 28 | B33: 19.6. klo 04 | C33: A | D33: Meksiko | E33: - | F33: Etelä-Korea | H33: -
A34: 29 | B34: 20.6. klo 04 | C34: C | D34: Brasilia | E34: - | F34: Haiti | H34: -
A35: 30 | B35: 20.6. klo 01 | C35: C | D35: Skotlanti | E35: - | F35: Marokko | H35: -
A36: 31 | B36: 20.6. klo 07 | C36: D | D36: Turkki | E36: - | F36: Paraguay | H36: -
... A77: 72 | B77: 28.6. klo 02.30 | C77: K | D77: Kongon DR | E77: - | F77: Uzbekistan | H77: -

Sheet Pisteet
A1: MM 2026 - veikkaajien pisteet
A2: Yhteenveto päivittyy Tulokset-välilehdelle syötettyjen toteutuneiden tulosten perusteella.
A3: ="Pelattuja otteluita: "&COUNTIFS(Tulokset!$G$6:$G$77,">=0",Tulokset!$I$6:$I$77,">=0")&" / 72" -> Pelattuja otteluita: 0 / 72
A5: Sija | B5: Välilehti | C5: Osallistuja | D5: Ottelupisteet | E5: Lohkopisteet | F5: Finaali/3-4 | G5: Yhteensä | H5: Täsmälleen oikein | J5: Tasatilanteet
A6: =IF($G6="","",1+COUNTIFS($G$6:$G$35,">"&$G6)+COUNTIFS($G$6:$G$35,$G6,$H$6:$H$35,">"&$H6)) -> 1 | B6: 1 | C6: =IF(Laskenta!$B4="","",Laskenta!$B4) -> Mike Salmon | D6: =IF($C6="","",Laskenta!$C4) -> 0 | E6: =IF($C6="","",Laskenta!$D4) -> 0 | F6: =IF($C6="","",Laskenta!$E4) -> 0 | G6: =IF($C6="","",Laskenta!$F4) -> 0 | H6: =IF($C6="","",Laskenta!$G4) -> 0 | J6: Sija huomioi ensin kokonaispisteet ja sen jälkeen täsmälleen oikein veikatut ottelut.
A7: =IF($G7="","",1+COUNTIFS($G$6:$G$35,">"&$G7)+COUNTIFS($G$6:$G$35,$G7,$H$6:$H$35,">"&$H7)) -> 1 | B7: 2 | C7: =IF(Laskenta!$B5="","",Laskenta!$B5) -> ArtsiKerho | D7: =IF($C7="","",Laskenta!$C5) -> 0 | E7: =IF($C7="","",Laskenta!$D5) -> 0 | F7: =IF($C7="","",Laskenta!$E5) -> 0 | G7: =IF($C7="","",Laskenta!$F5) -> 0 | H7: =IF($C7="","",Laskenta!$G5) -> 0
A8: =IF($G8="","",1+COUNTIFS($G$6:$G$35,">"&$G8)+COUNTIFS($G$6:$G$35,$G8,$H$6:$H$35,">"&$H8)) -> 1 | B8: 3 | C8: =IF(Laskenta!$B6="","",Laskenta!$B6) -> Johnny Rotten | D8: =IF($C8="","",Laskenta!$C6) -> 0 | E8: =IF($C8="","",Laskenta!$D6) -> 0 | F8: =IF($C8="","",Laskenta!$E6) -> 0 | G8: =IF($C8="","",Laskenta!$F6) -> 0 | H8: =IF($C8="","",Laskenta!$G6) -> 0 | J8: Pisteytystiivistelmä
A9: =IF($G9="","",1+COUNTIFS($G$6:$G$35,">"&$G9)+COUNTIFS($G$6:$G$35,$G9,$H$6:$H$35,">"&$H9)) -> 1 | B9: 4 | C9: =IF(Laskenta!$B7="","",Laskenta!$B7) -> The Moka | D9: =IF($C9="","",Laskenta!$C7) -> 0 | E9: =IF($C9="","",Laskenta!$D7) -> 0 | F9: =IF($C9="","",Laskenta!$E7) -> 0 | G9: =IF($C9="","",Laskenta!$F7) -> 0 | H9: =IF($C9="","",Laskenta!$G7) -> 0 | J9: Ottelut: 1-X-2 pitää olla oikein. Täysin oikea tulos 6 p.
A10: =IF($G10="","",1+COUNTIFS($G$6:$G$35,">"&$G10)+COUNTIFS($G$6:$G$35,$G10,$H$6:$H$35,">"&$H10)) -> 1 | B10: 5 | C10: =IF(Laskenta!$B8="","",Laskenta!$B8) -> Sedu | D10: =IF($C10="","",Laskenta!$C8) -> 0 | E10: =IF($C10="","",Laskenta!$D8) -> 0 | F10: =IF($C10="","",Laskenta!$E8) -> 0 | G10: =IF($C10="","",Laskenta!$F8) -> 0 | H10: =IF($C10="","",Laskenta!$G8) -> 0 | J10: Ei-tasapelit: oikea 1-X-2 on edellytys; pisteet = max(0, 6 - maalimäärävirheiden summa).
A11: =IF($G11="","",1+COUNTIFS($G$6:$G$35,">"&$G11)+COUNTIFS($G$6:$G$35,$G11,$H$6:$H$35,">"&$H11)) -> 1 | B11: 6 | C11: =IF(Laskenta!$B9="","",Laskenta!$B9) -> Pauli Koponen | D11: =IF($C11="","",Laskenta!$C9) -> 0 | E11: =IF($C11="","",Laskenta!$D9) -> 0 | F11: =IF($C11="","",Laskenta!$E9) -> 0 | G11: =IF($C11="","",Laskenta!$F9) -> 0 | H11: =IF($C11="","",Laskenta!$G9) -> 0 | J11: Esim. tulos 5-1 ja veikkaus 1-0: virhe 4+1=5, pisteet 6-5=1.
A12: =IF($G12="","",1+COUNTIFS($G$6:$G$35,">"&$G12)+COUNTIFS($G$6:$G$35,$G12,$H$6:$H$35,">"&$H12)) -> 1 | B12: 7 | C12: =IF(Laskenta!$B10="","",Laskenta!$B10) -> Pora | D12: =IF($C12="","",Laskenta!$C10) -> 0 | E12: =IF($C12="","",Laskenta!$D10) -> 0 | F12: =IF($C12="","",Laskenta!$E10) -> 0 | G12: =IF($C12="","",Laskenta!$F10) -> 0 | H12: =IF($C12="","",Laskenta!$G10) -> 0 | J12: Tasapelit: täysin oikea tasapeli 6 p, muu oikea tasapeli 3 p.
A13: =IF($G13="","",1+COUNTIFS($G$6:$G$35,">"&$G13)+COUNTIFS($G$6:$G$35,$G13,$H$6:$H$35,">"&$H13)) -> 1 | B13: 8 | C13: =IF(Laskenta!$B11="","",Laskenta!$B11) -> Rikhard Moeller-Kalanmaksaoeljy | D13: =IF($C13="","",Laskenta!$C11) -> 0 | E13: =IF($C13="","",Laskenta!$D11) -> 0 | F13: =IF($C13="","",Laskenta!$E11) -> 0 | G13: =IF($C13="","",Laskenta!$F11) -> 0 | H13: =IF($C13="","",Laskenta!$G11) -> 0 | J13: Finaali ja sijat 3-4: jokainen oikea joukkue kategoriassa 2 p.
A14: =IF($G14="","",1+COUNTIFS($G$6:$G$35,">"&$G14)+COUNTIFS($G$6:$G$35,$G14,$H$6:$H$35,">"&$H14)) -> 1 | B14: 9 | C14: =IF(Laskenta!$B12="","",Laskenta!$B12) -> Tuurilla | D14: =IF($C14="","",Laskenta!$C12) -> 0 | E14: =IF($C14="","",Laskenta!$D12) -> 0 | F14: =IF($C14="","",Laskenta!$E12) -> 0 | G14: =IF($C14="","",Laskenta!$F12) -> 0 | H14: =IF($C14="","",Laskenta!$G12) -> 0
A15: =IF($G15="","",1+COUNTIFS($G$6:$G$35,">"&$G15)+COUNTIFS($G$6:$G$35,$G15,$H$6:$H$35,">"&$H15)) -> 1 | B15: 10 | C15: =IF(Laskenta!$B13="","",Laskenta!$B13) -> PoHan Pullistus | D15: =IF($C15="","",Laskenta!$C13) -> 0 | E15: =IF($C15="","",Laskenta!$D13) -> 0 | F15: =IF($C15="","",Laskenta!$E13) -> 0 | G15: =IF($C15="","",Laskenta!$F13) -> 0 | H15: =IF($C15="","",Laskenta!$G13) -> 0
A16: =IF($G16="","",1+COUNTIFS($G$6:$G$35,">"&$G16)+COUNTIFS($G$6:$G$35,$G16,$H$6:$H$35,">"&$H16)) -> 1 | B16: 11 | C16: =IF(Laskenta!$B14="","",Laskenta!$B14) -> Profeetta Möttönen | D16: =IF($C16="","",Laskenta!$C14) -> 0 | E16: =IF($C16="","",Laskenta!$D14) -> 0 | F16: =IF($C16="","",Laskenta!$E14) -> 0 | G16: =IF($C16="","",Laskenta!$F14) -> 0 | H16: =IF($C16="","",Laskenta!$G14) -> 0
A17: =IF($G17="","",1+COUNTIFS($G$6:$G$35,">"&$G17)+COUNTIFS($G$6:$G$35,$G17,$H$6:$H$35,">"&$H17)) -> 1 | B17: 12 | C17: =IF(Laskenta!$B15="","",Laskenta!$B15) -> Xhakku | D17: =IF($C17="","",Laskenta!$C15) -> 0 | E17: =IF($C17="","",Laskenta!$D15) -> 0 | F17: =IF($C17="","",Laskenta!$E15) -> 0 | G17: =IF($C17="","",Laskenta!$F15) -> 0 | H17: =IF($C17="","",Laskenta!$G15) -> 0
A18: =IF($G18="","",1+COUNTIFS($G$6:$G$35,">"&$G18)+COUNTIFS($G$6:$G$35,$G18,$H$6:$H$35,">"&$H18)) -> 1 | B18: 13 | C18: =IF(Laskenta!$B16="","",Laskenta!$B16) -> Ice Cold | D18: =IF($C18="","",Laskenta!$C16) -> 0 | E18: =IF($C18="","",Laskenta!$D16) -> 0 | F18: =IF($C18="","",Laskenta!$E16) -> 0 | G18: =IF($C18="","",Laskenta!$F16) -> 0 | H18: =IF($C18="","",Laskenta!$G16) -> 0
A19: =IF($G19="","",1+COUNTIFS($G$6:$G$35,">"&$G19)+COUNTIFS($G$6:$G$35,$G19,$H$6:$H$35,">"&$H19)) -> 1 | B19: 14 | C19: =IF(Laskenta!$B17="","",Laskenta!$B17) -> Eski66 | D19: =IF($C19="","",Laskenta!$C17) -> 0 | E19: =IF($C19="","",Laskenta!$D17) -> 0 | F19: =IF($C19="","",Laskenta!$E17) -> 0 | G19: =IF($C19="","",Laskenta!$F17) -> 0 | H19: =IF($C19="","",Laskenta!$G17) -> 0
A20: =IF($G20="","",1+COUNTIFS($G$6:$G$35,">"&$G20)+COUNTIFS($G$6:$G$35,$G20,$H$6:$H$35,">"&$H20)) -> 1 | B20: 15 | C20: =IF(Laskenta!$B18="","",Laskenta!$B18) -> Suomaldinho | D20: =IF($C20="","",Laskenta!$C18) -> 0 | E20: =IF($C20="","",Laskenta!$D18) -> 0 | F20: =IF($C20="","",Laskenta!$E18) -> 0 | G20: =IF($C20="","",Laskenta!$F18) -> 0 | H20: =IF($C20="","",Laskenta!$G18) -> 0
A21: =IF($G21="","",1+COUNTIFS($G$6:$G$35,">"&$G21)+COUNTIFS($G$6:$G$35,$G21,$H$6:$H$35,">"&$H21)) -> 1 | B21: 16 | C21: =IF(Laskenta!$B19="","",Laskenta!$B19) -> Sipolovic | D21: =IF($C21="","",Laskenta!$C19) -> 0 | E21: =IF($C21="","",Laskenta!$D19) -> 0 | F21: =IF($C21="","",Laskenta!$E19) -> 0 | G21: =IF($C21="","",Laskenta!$F19) -> 0 | H21: =IF($C21="","",Laskenta!$G19) -> 0
A22: =IF($G22="","",1+COUNTIFS($G$6:$G$35,">"&$G22)+COUNTIFS($G$6:$G$35,$G22,$H$6:$H$35,">"&$H22)) -> 1 | B22: 17 | C22: =IF(Laskenta!$B20="","",Laskenta!$B20) -> Ibaldo de Lima | D22: =IF($C22="","",Laskenta!$C20) -> 0 | E22: =IF($C22="","",Laskenta!$D20) -> 0 | F22: =IF($C22="","",Laskenta!$E20) -> 0 | G22: =IF($C22="","",Laskenta!$F20) -> 0 | H22: =IF($C22="","",Laskenta!$G20) -> 0
A23: =IF($G23="","",1+COUNTIFS($G$6:$G$35,">"&$G23)+COUNTIFS($G$6:$G$35,$G23,$H$6:$H$35,">"&$H23)) -> 1 | B23: 18 | C23: =IF(Laskenta!$B21="","",Laskenta!$B21) -> Teo ja Noel | D23: =IF($C23="","",Laskenta!$C21) -> 0 | E23: =IF($C23="","",Laskenta!$D21) -> 0 | F23: =IF($C23="","",Laskenta!$E21) -> 0 | G23: =IF($C23="","",Laskenta!$F21) -> 0 | H23: =IF($C23="","",Laskenta!$G21) -> 0
A24: =IF($G24="","",1+COUNTIFS($G$6:$G$35,">"&$G24)+COUNTIFS($G$6:$G$35,$G24,$H$6:$H$35,">"&$H24)) -> 1 | B24: 19 | C24: =IF(Laskenta!$B22="","",Laskenta!$B22) -> Shampoo | D24: =IF($C24="","",Laskenta!$C22) -> 0 | E24: =IF($C24="","",Laskenta!$D22) -> 0 | F24: =IF($C24="","",Laskenta!$E22) -> 0 | G24: =IF($C24="","",Laskenta!$F22) -> 0 | H24: =IF($C24="","",Laskenta!$G22) -> 0
A25: =IF($G25="","",1+COUNTIFS($G$6:$G$35,">"&$G25)+COUNTIFS($G$6:$G$35,$G25,$H$6:$H$35,">"&$H25)) -> 1 | B25: 20 | C25: =IF(Laskenta!$B23="","",Laskenta!$B23) -> Tero H | D25: =IF($C25="","",Laskenta!$C23) -> 0 | E25: =IF($C25="","",Laskenta!$D23) -> 0 | F25: =IF($C25="","",Laskenta!$E23) -> 0 | G25: =IF($C25="","",Laskenta!$F23) -> 0 | H25: =IF($C25="","",Laskenta!$G23) -> 0
... A35: =IF($G35="","",1+COUNTIFS($G$6:$G$35,">"&$G35)+COUNTIFS($G$6:$G$35,$G35,$H$6:$H$35,">"&$H35)) | B35: 30 | C35: =IF(Laskenta!$B33="","",Laskenta!$B33) | D35: =IF($C35="","",Laskenta!$C33) | E35: =IF($C35="","",Laskenta!$D33) | F35: =IF($C35="","",Laskenta!$E33) | G35: =IF($C35="","",Laskenta!$F33) | H35: =IF($C35="","",Laskenta!$G33)

Sheet Laskenta
A1: Laskenta - älä muokkaa
A2: Täällä ovat pisteytyskaavat. Veikkausvälilehdillä 1-30 ei ole pisteytyskaavoja. Ottelupisteissä oikea 1-X-2 on edellytys; ei erillistä voittajapistettä. Ei-tasapeleissä pisteet = max(0, 6 - maalimäärävirheiden summa).
A3: Välilehti | B3: Osallistuja | C3: Ottelupisteet | D3: Lohkopisteet | E3: Finaali/3-4-pisteet | F3: Yhteensä | G3: Täsmälleen oikein | H3: Ottelu 1 | I3: Ottelu 2 | J3: Ottelu 3 | K3: Ottelu 4 | L3: Ottelu 5 | M3: Ottelu 6 | N3: Ottelu 7 | O3: Ottelu 8 | P3: Ottelu 9 | Q3: Ottelu 10 | R3: Ottelu 11 | S3: Ottelu 12 | T3: Ottelu 13 | U3: Ottelu 14 | V3: Ottelu 15 | W3: Ottelu 16 | X3: Ottelu 17 | Y3: Ottelu 18 | Z3: Ottelu 19 | AA3: Ottelu 20 | AB3: Ottelu 21 | AC3: Ottelu 22 | AD3: Ottelu 23 | AE3: Ottelu 24 | AF3: Ottelu 25 | AG3: Ottelu 26 | AH3: Ottelu 27 | AI3: Ottelu 28 | AJ3: Ottelu 29 | AK3: Ottelu 30 | AL3: Ottelu 31 | AM3: Ottelu 32 | AN3: Ottelu 33 | AO3: Ottelu 34 | AP3: Ottelu 35 | AQ3: Ottelu 36 | AR3: Ottelu 37 | AS3: Ottelu 38 | AT3: Ottelu 39 | AU3: Ottelu 40 | AV3: Ottelu 41 | AW3: Ottelu 42 | AX3: Ottelu 43 | AY3: Ottelu 44 | AZ3: Ottelu 45 | BA3: Ottelu 46 | BB3: Ottelu 47 | BC3: Ottelu 48 | BD3: Ottelu 49 | BE3: Ottelu 50 | BF3: Ottelu 51 | BG3: Ottelu 52 | BH3: Ottelu 53 | BI3: Ottelu 54 | BJ3: Ottelu 55 | BK3: Ottelu 56 | BL3: Ottelu 57 | BM3: Ottelu 58 | BN3: Ottelu 59 | BO3: Ottelu 60 | BP3: Ottelu 61 | BQ3: Ottelu 62 | BR3: Ottelu 63 | BS3: Ottelu 64 | BT3: Ottelu 65 | BU3: Ottelu 66 | BV3: Ottelu 67 | BW3: Ottelu 68 | BX3: Ottelu 69 | BY3: Ottelu 70 | BZ3: Ottelu 71 | CA3: Ottelu 72 | CC3: Lohko 1 | CD3: Lohko 2 | CE3: Lohko 3 | CF3: Lohko 4 | CG3: Lohko 5 | CH3: Lohko 6 | CI3: Lohko 7 | CJ3: Lohko 8 | CK3: Lohko 9 | CL3: Lohko 10 | CM3: Lohko 11 | CN3: Lohko 12 | CO3: Lohko 13 | CP3: Lohko 14 | CQ3: Lohko 15 | CR3: Lohko 16 | CS3: Lohko 17 | CT3: Lohko 18 | CU3: Lohko 19 | CV3: Lohko 20 | CW3: Lohko 21 | CX3: Lohko 22 | CY3: Lohko 23 | CZ3: Lohko 24 | DA3: Lohko 25 | DB3: Lohko 26 | DC3: Lohko 27 | DD3: Lohko 28 | DE3: Lohko 29 | DF3: Lohko 30 | DG3: Lohko 31 | DH3: Lohko 32 | DI3: Lohko 33 | DJ3: Lohko 34 | DK3: Lohko 35 | DL3: Lohko 36 | DM3: Lohko 37 | DN3: Lohko 38 | DO3: Lohko 39 | DP3: Lohko 40 | DQ3: Lohko 41 | DR3: Lohko 42 | DS3: Lohko 43 | DT3: Lohko 44 | DU3: Lohko 45 | DV3: Lohko 46 | DW3: Lohko 47 | DX3: Lohko 48 | DZ3: Finalisti 1 | EA3: Finalisti 2 | EB3: Sijat 3-4 / 1 | EC3: Sijat 3-4 / 2
A4: 1 | B4: =IF(INDIRECT("'"&$A4&"'!$H$2")="","",INDIRECT("'"&$A4&"'!$H$2")) -> Mike Salmon | C4: =SUM(H4:CA4) -> 0 | D4: =SUM(CD4:DY4) -> 0 | E4: =SUM(EA4:ED4) -> 0 | F4: =IF(B4="","",SUM(C4:E4)) -> 0 | G4: =COUNTIF(H4:CA4,6) -> 0 | H4: =IF(OR(Tulokset!$G$6="",Tulokset!$I$6="",'1'!$I$7="",'1'!$K$7=""),"",IF(SIGN('1'!$I$7-'1'!$K$7)<>SIGN(Tulokset!$G$6-Tulokset!$I$6),0,IF(Tulokset!$G$6=Tulokset!$I$6,IF(AND('1'!$I$7=Tulokset!$G$6,'1'!$K$7=Tulokset!$I$6),6,3),MAX(0,6-(ABS('1'!$I$7-Tulokset!$G$6)+ABS('1'!$K$7-Tulokset!$I$6)))))) | I4: =IF(OR(Tulokset!$G$7="",Tulokset!$I$7="",'1'!$I$8="",'1'!$K$8=""),"",IF(SIGN('1'!$I$8-'1'!$K$8)<>SIGN(Tulokset!$G$7-Tulokset!$I$7),0,IF(Tulokset!$G$7=Tulokset!$I$7,IF(AND('1'!$I$8=Tulokset!$G$7,'1'!$K$8=Tulokset!$I$7),6,3),MAX(0,6-(ABS('1'!$I$8-Tulokset!$G$7)+ABS('1'!$K$8-Tulokset!$I$7)))))) | J4: =IF(OR(Tulokset!$G$8="",Tulokset!$I$8="",'1'!$I$9="",'1'!$K$9=""),"",IF(SIGN('1'!$I$9-'1'!$K$9)<>SIGN(Tulokset!$G$8-Tulokset!$I$8),0,IF(Tulokset!$G$8=Tulokset!$I$8,IF(AND('1'!$I$9=Tulokset!$G$8,'1'!$K$9=Tulokset!$I$8),6,3),MAX(0,6-(ABS('1'!$I$9-Tulokset!$G$8)+ABS('1'!$K$9-Tulokset!$I$8)))))) | K4: =IF(OR(Tulokset!$G$9="",Tulokset!$I$9="",'1'!$I$10="",'1'!$K$10=""),"",IF(SIGN('1'!$I$10-'1'!$K$10)<>SIGN(Tulokset!$G$9-Tulokset!$I$9),0,IF(Tulokset!$G$9=Tulokset!$I$9,IF(AND('1'!$I$10=Tulokset!$G$9,'1'!$K$10=Tulokset!$I$9),6,3),MAX(0,6-(ABS('1'!$I$10-Tulokset!$G$9)+ABS('1'!$K$10-Tulokset!$I$9)))))) | L4: =IF(OR(Tulokset!$G$10="",Tulokset!$I$10="",'1'!$I$11="",'1'!$K$11=""),"",IF(SIGN('1'!$I$11-'1'!$K$11)<>SIGN(Tulokset!$G$10-Tulokset!$I$10),0,IF(Tulokset!$G$10=Tulokset!$I$10,IF(AND('1'!$I$11=Tulokset!$G$10,'1'!$K$11=Tulokset!$I$10),6,3),MAX(0,6-(ABS('1'!$I$11-Tulokset!$G$10)+ABS('1'!$K$11-Tulokset!$I$10)))))) | M4: =IF(OR(Tulokset!$G$11="",Tulokset!$I$11="",'1'!$I$12="",'1'!$K$12=""),"",IF(SIGN('1'!$I$12-'1'!$K$12)<>SIGN(Tulokset!$G$11-Tulokset!$I$11),0,IF(Tulokset!$G$11=Tulokset!$I$11,IF(AND('1'!$I$12=Tulokset!$G$11,'1'!$K$12=Tulokset!$I$11),6,3),MAX(0,6-(ABS('1'!$I$12-Tulokset!$G$11)+ABS('1'!$K$12-Tulokset!$I$11)))))) | N4: =IF(OR(Tulokset!$G$12="",Tulokset!$I$12="",'1'!$I$13="",'1'!$K$13=""),"",IF(SIGN('1'!$I$13-'1'!$K$13)<>SIGN(Tulokset!$G$12-Tulokset!$I$12),0,IF(Tulokset!$G$12=Tulokset!$I$12,IF(AND('1'!$I$13=Tulokset!$G$12,'1'!$K$13=Tulokset!$I$12),6,3),MAX(0,6-(ABS('1'!$I$13-Tulokset!$G$12)+ABS('1'!$K$13-Tulokset!$I$12)))))) | O4: =IF(OR(Tulokset!$G$13="",Tulokset!$I$13="",'1'!$I$14="",'1'!$K$14=""),"",IF(SIGN('1'!$I$14-'1'!$K$14)<>SIGN(Tulokset!$G$13-Tulokset!$I$13),0,IF(Tulokset!$G$13=Tulokset!$I$13,IF(AND('1'!$I$14=Tulokset!$G$13,'1'!$K$14=Tulokset!$I$13),6,3),MAX(0,6-(ABS('1'!$I$14-Tulokset!$G$13)+ABS('1'!$K$14-Tulokset!$I$13)))))) | P4: =IF(OR(Tulokset!$G$14="",Tulokset!$I$14="",'1'!$I$15="",'1'!$K$15=""),"",IF(SIGN('1'!$I$15-'1'!$K$15)<>SIGN(Tulokset!$G$14-Tulokset!$I$14),0,IF(Tulokset!$G$14=Tulokset!$I$14,IF(AND('1'!$I$15=Tulokset!$G$14,'1'!$K$15=Tulokset!$I$14),6,3),MAX(0,6-(ABS('1'!$I$15-Tulokset!$G$14)+ABS('1'!$K$15-Tulokset!$I$14)))))) | Q4: =IF(OR(Tulokset!$G$15="",Tulokset!$I$15="",'1'!$I$16="",'1'!$K$16=""),"",IF(SIGN('1'!$I$16-'1'!$K$16)<>SIGN(Tulokset!$G$15-Tulokset!$I$15),0,IF(Tulokset!$G$15=Tulokset!$I$15,IF(AND('1'!$I$16=Tulokset!$G$15,'1'!$K$16=Tulokset!$I$15),6,3),MAX(0,6-(ABS('1'!$I$16-Tulokset!$G$15)+ABS('1'!$K$16-Tulokset!$I$15)))))) | R4: =IF(OR(Tulokset!$G$16="",Tulokset!$I$16="",'1'!$I$17="",'1'!$K$17=""),"",IF(SIGN('1'!$I$17-'1'!$K$17)<>SIGN(Tulokset!$G$16-Tulokset!$I$16),0,IF(Tulokset!$G$16=Tulokset!$I$16,IF(AND('1'!$I$17=Tulokset!$G$16,'1'!$K$17=Tulokset!$I$16),6,3),MAX(0,6-(ABS('1'!$I$17-Tulokset!$G$16)+ABS('1'!$K$17-Tulokset!$I$16)))))) | S4: =IF(OR(Tulokset!$G$17="",Tulokset!$I$17="",'1'!$I$18="",'1'!$K$18=""),"",IF(SIGN('1'!$I$18-'1'!$K$18)<>SIGN(Tulokset!$G$17-Tulokset!$I$17),0,IF(Tulokset!$G$17=Tulokset!$I$17,IF(AND('1'!$I$18=Tulokset!$G$17,'1'!$K$18=Tulokset!$I$17),6,3),MAX(0,6-(ABS('1'!$I$18-Tulokset!$G$17)+ABS('1'!$K$18-Tulokset!$I$17)))))) | T4: =IF(OR(Tulokset!$G$18="",Tulokset!$I$18="",'1'!$I$19="",'1'!$K$19=""),"",IF(SIGN('1'!$I$19-'1'!$K$19)<>SIGN(Tulokset!$G$18-Tulokset!$I$18),0,IF(Tulokset!$G$18=Tulokset!$I$18,IF(AND('1'!$I$19=Tulokset!$G$18,'1'!$K$19=Tulokset!$I$18),6,3),MAX(0,6-(ABS('1'!$I$19-Tulokset!$G$18)+ABS('1'!$K$19-Tulokset!$I$18)))))) | U4: =IF(OR(Tulokset!$G$19="",Tulokset!$I$19="",'1'!$I$20="",'1'!$K$20=""),"",IF(SIGN('1'!$I$20-'1'!$K$20)<>SIGN(Tulokset!$G$19-Tulokset!$I$19),0,IF(Tulokset!$G$19=Tulokset!$I$19,IF(AND('1'!$I$20=Tulokset!$G$19,'1'!$K$20=Tulokset!$I$19),6,3),MAX(0,6-(ABS('1'!$I$20-Tulokset!$G$19)+ABS('1'!$K$20-Tulokset!$I$19)))))) | V4: =IF(OR(Tulokset!$G$20="",Tulokset!$I$20="",'1'!$I$21="",'1'!$K$21=""),"",IF(SIGN('1'!$I$21-'1'!$K$21)<>SIGN(Tulokset!$G$20-Tulokset!$I$20),0,IF(Tulokset!$G$20=Tulokset!$I$20,IF(AND('1'!$I$21=Tulokset!$G$20,'1'!$K$21=Tulokset!$I$20),6,3),MAX(0,6-(ABS('1'!$I$21-Tulokset!$G$20)+ABS('1'!$K$21-Tulokset!$I$20)))))) | W4: =IF(OR(Tulokset!$G$21="",Tulokset!$I$21="",'1'!$I$22="",'1'!$K$22=""),"",IF(SIGN('1'!$I$22-'1'!$K$22)<>SIGN(Tulokset!$G$21-Tulokset!$I$21),0,IF(Tulokset!$G$21=Tulokset!$I$21,IF(AND('1'!$I$22=Tulokset!$G$21,'1'!$K$22=Tulokset!$I$21),6,3),MAX(0,6-(ABS('1'!$I$22-Tulokset!$G$21)+ABS('1'!$K$22-Tulokset!$I$21)))))) | X4: =IF(OR(Tulokset!$G$22="",Tulokset!$I$22="",'1'!$I$23="",'1'!$K$23=""),"",IF(SIGN('1'!$I$23-'1'!$K$23)<>SIGN(Tulokset!$G$22-Tulokset!$I$22),0,IF(Tulokset!$G$22=Tulokset!$I$22,IF(AND('1'!$I$23=Tulokset!$G$22,'1'!$K$23=Tulokset!$I$22),6,3),MAX(0,6-(ABS('1'!$I$23-Tulokset!$G$22)+ABS('1'!$K$23-Tulokset!$I$22)))))) | Y4: =IF(OR(Tulokset!$G$23="",Tulokset!$I$23="",'1'!$I$24="",'1'!$K$24=""),"",IF(SIGN('1'!$I$24-'1'!$K$24)<>SIGN(Tulokset!$G$23-Tulokset!$I$23),0,IF(Tulokset!$G$23=Tulokset!$I$23,IF(AND('1'!$I$24=Tulokset!$G$23,'1'!$K$24=Tulokset!$I$23),6,3),MAX(0,6-(ABS('1'!$I$24-Tulokset!$G$23)+ABS('1'!$K$24-Tulokset!$I$23)))))) | Z4: =IF(OR(Tulokset!$G$24="",Tulokset!$I$24="",'1'!$I$25="",'1'!$K$25=""),"",IF(SIGN('1'!$I$25-'1'!$K$25)<>SIGN(Tulokset!$G$24-Tulokset!$I$24),0,IF(Tulokset!$G$24=Tulokset!$I$24,IF(AND('1'!$I$25=Tulokset!$G$24,'1'!$K$25=Tulokset!$I$24),6,3),MAX(0,6-(ABS('1'!$I$25-Tulokset!$G$24)+ABS('1'!$K$25-Tulokset!$I$24)))))) | AA4: =IF(OR(Tulokset!$G$25="",Tulokset!$I$25="",'1'!$I$26="",'1'!$K$26=""),"",IF(SIGN('1'!$I$26-'1'!$K$26)<>SIGN(Tulokset!$G$25-Tulokset!$I$25),0,IF(Tulokset!$G$25=Tulokset!$I$25,IF(AND('1'!$I$26=Tulokset!$G$25,'1'!$K$26=Tulokset!$I$25),6,3),MAX(0,6-(ABS('1'!$I$26-Tulokset!$G$25)+ABS('1'!$K$26-Tulokset!$I$25)))))) | AB4: =IF(OR(Tulokset!$G$26="",Tulokset!$I$26="",'1'!$I$27="",'1'!$K$27=""),"",IF(SIGN('1'!$I$27-'1'!$K$27)<>SIGN(Tulokset!$G$26-Tulokset!$I$26),0,IF(Tulokset!$G$26=Tulokset!$I$26,IF(AND('1'!$I$27=Tulokset!$G$26,'1'!$K$27=Tulokset!$I$26),6,3),MAX(0,6-(ABS('1'!$I$27-Tulokset!$G$26)+ABS('1'!$K$27-Tulokset!$I$26)))))) | AC4: =IF(OR(Tulokset!$G$27="",Tulokset!$I$27="",'1'!$I$28="",'1'!$K$28=""),"",IF(SIGN('1'!$I$28-'1'!$K$28)<>SIGN(Tulokset!$G$27-Tulokset!$I$27),0,IF(Tulokset!$G$27=Tulokset!$I$27,IF(AND('1'!$I$28=Tulokset!$G$27,'1'!$K$28=Tulokset!$I$27),6,3),MAX(0,6-(ABS('1'!$I$28-Tulokset!$G$27)+ABS('1'!$K$28-Tulokset!$I$27)))))) | AD4: =IF(OR(Tulokset!$G$28="",Tulokset!$I$28="",'1'!$I$29="",'1'!$K$29=""),"",IF(SIGN('1'!$I$29-'1'!$K$29)<>SIGN(Tulokset!$G$28-Tulokset!$I$28),0,IF(Tulokset!$G$28=Tulokset!$I$28,IF(AND('1'!$I$29=Tulokset!$G$28,'1'!$K$29=Tulokset!$I$28),6,3),MAX(0,6-(ABS('1'!$I$29-Tulokset!$G$28)+ABS('1'!$K$29-Tulokset!$I$28)))))) | AE4: =IF(OR(Tulokset!$G$29="",Tulokset!$I$29="",'1'!$I$30="",'1'!$K$30=""),"",IF(SIGN('1'!$I$30-'1'!$K$30)<>SIGN(Tulokset!$G$29-Tulokset!$I$29),0,IF(Tulokset!$G$29=Tulokset!$I$29,IF(AND('1'!$I$30=Tulokset!$G$29,'1'!$K$30=Tulokset!$I$29),6,3),MAX(0,6-(ABS('1'!$I$30-Tulokset!$G$29)+ABS('1'!$K$30-Tulokset!$I$29)))))) | AF4: =IF(OR(Tulokset!$G$30="",Tulokset!$I$30="",'1'!$I$31="",'1'!$K$31=""),"",IF(SIGN('1'!$I$31-'1'!$K$31)<>SIGN(Tulokset!$G$30-Tulokset!$I$30),0,IF(Tulokset!$G$30=Tulokset!$I$30,IF(AND('1'!$I$31=Tulokset!$G$30,'1'!$K$31=Tulokset!$I$30),6,3),MAX(0,6-(ABS('1'!$I$31-Tulokset!$G$30)+ABS('1'!$K$31-Tulokset!$I$30)))))) | AG4: =IF(OR(Tulokset!$G$31="",Tulokset!$I$31="",'1'!$I$32="",'1'!$K$32=""),"",IF(SIGN('1'!$I$32-'1'!$K$32)<>SIGN(Tulokset!$G$31-Tulokset!$I$31),0,IF(Tulokset!$G$31=Tulokset!$I$31,IF(AND('1'!$I$32=Tulokset!$G$31,'1'!$K$32=Tulokset!$I$31),6,3),MAX(0,6-(ABS('1'!$I$32-Tulokset!$G$31)+ABS('1'!$K$32-Tulokset!$I$31)))))) | AH4: =IF(OR(Tulokset!$G$32="",Tulokset!$I$32="",'1'!$I$33="",'1'!$K$33=""),"",IF(SIGN('1'!$I$33-'1'!$K$33)<>SIGN(Tulokset!$G$32-Tulokset!$I$32),0,IF(Tulokset!$G$32=Tulokset!$I$32,IF(AND('1'!$I$33=Tulokset!$G$32,'1'!$K$33=Tulokset!$I$32),6,3),MAX(0,6-(ABS('1'!$I$33-Tulokset!$G$32)+ABS('1'!$K$33-Tulokset!$I$32)))))) | AI4: =IF(OR(Tulokset!$G$33="",Tulokset!$I$33="",'1'!$I$34="",'1'!$K$34=""),"",IF(SIGN('1'!$I$34-'1'!$K$34)<>SIGN(Tulokset!$G$33-Tulokset!$I$33),0,IF(Tulokset!$G$33=Tulokset!$I$33,IF(AND('1'!$I$34=Tulokset!$G$33,'1'!$K$34=Tulokset!$I$33),6,3),MAX(0,6-(ABS('1'!$I$34-Tulokset!$G$33)+ABS('1'!$K$34-Tulokset!$I$33)))))) | AJ4: =IF(OR(Tulokset!$G$34="",Tulokset!$I$34="",'1'!$I$35="",'1'!$K$35=""),"",IF(SIGN('1'!$I$35-'1'!$K$35)<>SIGN(Tulokset!$G$34-Tulokset!$I$34),0,IF(Tulokset!$G$34=Tulokset!$I$34,IF(AND('1'!$I$35=Tulokset!$G$34,'1'!$K$35=Tulokset!$I$34),6,3),MAX(0,6-(ABS('1'!$I$35-Tulokset!$G$34)+ABS('1'!$K$35-Tulokset!$I$34)))))) | AK4: =IF(OR(Tulokset!$G$35="",Tulokset!$I$35="",'1'!$I$36="",'1'!$K$36=""),"",IF(SIGN('1'!$I$36-'1'!$K$36)<>SIGN(Tulokset!$G$35-Tulokset!$I$35),0,IF(Tulokset!$G$35=Tulokset!$I$35,IF(AND('1'!$I$36=Tulokset!$G$35,'1'!$K$36=Tulokset!$I$35),6,3),MAX(0,6-(ABS('1'!$I$36-Tulokset!$G$35)+ABS('1'!$K$36-Tulokset!$I$35)))))) | AL4: =IF(OR(Tulokset!$G$36="",Tulokset!$I$36="",'1'!$I$37="",'1'!$K$37=""),"",IF(SIGN('1'!$I$37-'1'!$K$37)<>SIGN(Tulokset!$G$36-Tulokset!$I$36),0,IF(Tulokset!$G$36=Tulokset!$I$36,IF(AND('1'!$I$37=Tulokset!$G$36,'1'!$K$37=Tulokset!$I$36),6,3),MAX(0,6-(ABS('1'!$I$37-Tulokset!$G$36)+ABS('1'!$K$37-Tulokset!$I$36)))))) | AM4: =IF(OR(Tulokset!$G$37="",Tulokset!$I$37="",'1'!$I$38="",'1'!$K$38=""),"",IF(SIGN('1'!$I$38-'1'!$K$38)<>SIGN(Tulokset!$G$37-Tulokset!$I$37),0,IF(Tulokset!$G$37=Tulokset!$I$37,IF(AND('1'!$I$38=Tulokset!$G$37,'1'!$K$38=Tulokset!$I$37),6,3),MAX(0,6-(ABS('1'!$I$38-Tulokset!$G$37)+ABS('1'!$K$38-Tulokset!$I$37)))))) | AN4: =IF(OR(Tulokset!$G$38="",Tulokset!$I$38="",'1'!$I$39="",'1'!$K$39=""),"",IF(SIGN('1'!$I$39-'1'!$K$39)<>SIGN(Tulokset!$G$38-Tulokset!$I$38),0,IF(Tulokset!$G$38=Tulokset!$I$38,IF(AND('1'!$I$39=Tulokset!$G$38,'1'!$K$39=Tulokset!$I$38),6,3),MAX(0,6-(ABS('1'!$I$39-Tulokset!$G$38)+ABS('1'!$K$39-Tulokset!$I$38)))))) | AO4: =IF(OR(Tulokset!$G$39="",Tulokset!$I$39="",'1'!$I$40="",'1'!$K$40=""),"",IF(SIGN('1'!$I$40-'1'!$K$40)<>SIGN(Tulokset!$G$39-Tulokset!$I$39),0,IF(Tulokset!$G$39=Tulokset!$I$39,IF(AND('1'!$I$40=Tulokset!$G$39,'1'!$K$40=Tulokset!$I$39),6,3),MAX(0,6-(ABS('1'!$I$40-Tulokset!$G$39)+ABS('1'!$K$40-Tulokset!$I$39)))))) | AP4: =IF(OR(Tulokset!$G$40="",Tulokset!$I$40="",'1'!$I$41="",'1'!$K$41=""),"",IF(SIGN('1'!$I$41-'1'!$K$41)<>SIGN(Tulokset!$G$40-Tulokset!$I$40),0,IF(Tulokset!$G$40=Tulokset!$I$40,IF(AND('1'!$I$41=Tulokset!$G$40,'1'!$K$41=Tulokset!$I$40),6,3),MAX(0,6-(ABS('1'!$I$41-Tulokset!$G$40)+ABS('1'!$K$41-Tulokset!$I$40)))))) | AQ4: =IF(OR(Tulokset!$G$41="",Tulokset!$I$41="",'1'!$I$42="",'1'!$K$42=""),"",IF(SIGN('1'!$I$42-'1'!$K$42)<>SIGN(Tulokset!$G$41-Tulokset!$I$41),0,IF(Tulokset!$G$41=Tulokset!$I$41,IF(AND('1'!$I$42=Tulokset!$G$41,'1'!$K$42=Tulokset!$I$41),6,3),MAX(0,6-(ABS('1'!$I$42-Tulokset!$G$41)+ABS('1'!$K$42-Tulokset!$I$41)))))) | AR4: =IF(OR(Tulokset!$G$42="",Tulokset!$I$42="",'1'!$I$43="",'1'!$K$43=""),"",IF(SIGN('1'!$I$43-'1'!$K$43)<>SIGN(Tulokset!$G$42-Tulokset!$I$42),0,IF(Tulokset!$G$42=Tulokset!$I$42,IF(AND('1'!$I$43=Tulokset!$G$42,'1'!$K$43=Tulokset!$I$42),6,3),MAX(0,6-(ABS('1'!$I$43-Tulokset!$G$42)+ABS('1'!$K$43-Tulokset!$I$42)))))) | AS4: =IF(OR(Tulokset!$G$43="",Tulokset!$I$43="",'1'!$I$44="",'1'!$K$44=""),"",IF(SIGN('1'!$I$44-'1'!$K$44)<>SIGN(Tulokset!$G$43-Tulokset!$I$43),0,IF(Tulokset!$G$43=Tulokset!$I$43,IF(AND('1'!$I$44=Tulokset!$G$43,'1'!$K$44=Tulokset!$I$43),6,3),MAX(0,6-(ABS('1'!$I$44-Tulokset!$G$43)+ABS('1'!$K$44-Tulokset!$I$43)))))) | AT4: =IF(OR(Tulokset!$G$44="",Tulokset!$I$44="",'1'!$I$45="",'1'!$K$45=""),"",IF(SIGN('1'!$I$45-'1'!$K$45)<>SIGN(Tulokset!$G$44-Tulokset!$I$44),0,IF(Tulokset!$G$44=Tulokset!$I$44,IF(AND('1'!$I$45=Tulokset!$G$44,'1'!$K$45=Tulokset!$I$44),6,3),MAX(0,6-(ABS('1'!$I$45-Tulokset!$G$44)+ABS('1'!$K$45-Tulokset!$I$44)))))) | AU4: =IF(OR(Tulokset!$G$45="",Tulokset!$I$45="",'1'!$I$46="",'1'!$K$46=""),"",IF(SIGN('1'!$I$46-'1'!$K$46)<>SIGN(Tulokset!$G$45-Tulokset!$I$45),0,IF(Tulokset!$G$45=Tulokset!$I$45,IF(AND('1'!$I$46=Tulokset!$G$45,'1'!$K$46=Tulokset!$I$45),6,3),MAX(0,6-(ABS('1'!$I$46-Tulokset!$G$45)+ABS('1'!$K$46-Tulokset!$I$45)))))) | AV4: =IF(OR(Tulokset!$G$46="",Tulokset!$I$46="",'1'!$I$47="",'1'!$K$47=""),"",IF(SIGN('1'!$I$47-'1'!$K$47)<>SIGN(Tulokset!$G$46-Tulokset!$I$46),0,IF(Tulokset!$G$46=Tulokset!$I$46,IF(AND('1'!$I$47=Tulokset!$G$46,'1'!$K$47=Tulokset!$I$46),6,3),MAX(0,6-(ABS('1'!$I$47-Tulokset!$G$46)+ABS('1'!$K$47-Tulokset!$I$46)))))) | AW4: =IF(OR(Tulokset!$G$47="",Tulokset!$I$47="",'1'!$I$48="",'1'!$K$48=""),"",IF(SIGN('1'!$I$48-'1'!$K$48)<>SIGN(Tulokset!$G$47-Tulokset!$I$47),0,IF(Tulokset!$G$47=Tulokset!$I$47,IF(AND('1'!$I$48=Tulokset!$G$47,'1'!$K$48=Tulokset!$I$47),6,3),MAX(0,6-(ABS('1'!$I$48-Tulokset!$G$47)+ABS('1'!$K$48-Tulokset!$I$47)))))) | AX4: =IF(OR(Tulokset!$G$48="",Tulokset!$I$48="",'1'!$I$49="",'1'!$K$49=""),"",IF(SIGN('1'!$I$49-'1'!$K$49)<>SIGN(Tulokset!$G$48-Tulokset!$I$48),0,IF(Tulokset!$G$48=Tulokset!$I$48,IF(AND('1'!$I$49=Tulokset!$G$48,'1'!$K$49=Tulokset!$I$48),6,3),MAX(0,6-(ABS('1'!$I$49-Tulokset!$G$48)+ABS('1'!$K$49-Tulokset!$I$48)))))) | AY4: =IF(OR(Tulokset!$G$49="",Tulokset!$I$49="",'1'!$I$50="",'1'!$K$50=""),"",IF(SIGN('1'!$I$50-'1'!$K$50)<>SIGN(Tulokset!$G$49-Tulokset!$I$49),0,IF(Tulokset!$G$49=Tulokset!$I$49,IF(AND('1'!$I$50=Tulokset!$G$49,'1'!$K$50=Tulokset!$I$49),6,3),MAX(0,6-(ABS('1'!$I$50-Tulokset!$G$49)+ABS('1'!$K$50-Tulokset!$I$49)))))) | AZ4: =IF(OR(Tulokset!$G$50="",Tulokset!$I$50="",'1'!$I$51="",'1'!$K$51=""),"",IF(SIGN('1'!$I$51-'1'!$K$51)<>SIGN(Tulokset!$G$50-Tulokset!$I$50),0,IF(Tulokset!$G$50=Tulokset!$I$50,IF(AND('1'!$I$51=Tulokset!$G$50,'1'!$K$51=Tulokset!$I$50),6,3),MAX(0,6-(ABS('1'!$I$51-Tulokset!$G$50)+ABS('1'!$K$51-Tulokset!$I$50)))))) | BA4: =IF(OR(Tulokset!$G$51="",Tulokset!$I$51="",'1'!$I$52="",'1'!$K$52=""),"",IF(SIGN('1'!$I$52-'1'!$K$52)<>SIGN(Tulokset!$G$51-Tulokset!$I$51),0,IF(Tulokset!$G$51=Tulokset!$I$51,IF(AND('1'!$I$52=Tulokset!$G$51,'1'!$K$52=Tulokset!$I$51),6,3),MAX(0,6-(ABS('1'!$I$52-Tulokset!$G$51)+ABS('1'!$K$52-Tulokset!$I$51)))))) | BB4: =IF(OR(Tulokset!$G$52="",Tulokset!$I$52="",'1'!$I$53="",'1'!$K$53=""),"",IF(SIGN('1'!$I$53-'1'!$K$53)<>SIGN(Tulokset!$G$52-Tulokset!$I$52),0,IF(Tulokset!$G$52=Tulokset!$I$52,IF(AND('1'!$I$53=Tulokset!$G$52,'1'!$K$53=Tulokset!$I$52),6,3),MAX(0,6-(ABS('1'!$I$53-Tulokset!$G$52)+ABS('1'!$K$53-Tulokset!$I$52)))))) | BC4: =IF(OR(Tulokset!$G$53="",Tulokset!$I$53="",'1'!$I$54="",'1'!$K$54=""),"",IF(SIGN('1'!$I$54-'1'!$K$54)<>SIGN(Tulokset!$G$53-Tulokset!$I$53),0,IF(Tulokset!$G$53=Tulokset!$I$53,IF(AND('1'!$I$54=Tulokset!$G$53,'1'!$K$54=Tulokset!$I$53),6,3),MAX(0,6-(ABS('1'!$I$54-Tulokset!$G$53)+ABS('1'!$K$54-Tulokset!$I$53)))))) | BD4: =IF(OR(Tulokset!$G$54="",Tulokset!$I$54="",'1'!$I$55="",'1'!$K$55=""),"",IF(SIGN('1'!$I$55-'1'!$K$55)<>SIGN(Tulokset!$G$54-Tulokset!$I$54),0,IF(Tulokset!$G$54=Tulokset!$I$54,IF(AND('1'!$I$55=Tulokset!$G$54,'1'!$K$55=Tulokset!$I$54),6,3),MAX(0,6-(ABS('1'!$I$55-Tulokset!$G$54)+ABS('1'!$K$55-Tulokset!$I$54)))))) | BE4: =IF(OR(Tulokset!$G$55="",Tulokset!$I$55="",'1'!$I$56="",'1'!$K$56=""),"",IF(SIGN('1'!$I$56-'1'!$K$56)<>SIGN(Tulokset!$G$55-Tulokset!$I$55),0,IF(Tulokset!$G$55=Tulokset!$I$55,IF(AND('1'!$I$56=Tulokset!$G$55,'1'!$K$56=Tulokset!$I$55),6,3),MAX(0,6-(ABS('1'!$I$56-Tulokset!$G$55)+ABS('1'!$K$56-Tulokset!$I$55)))))) | BF4: =IF(OR(Tulokset!$G$56="",Tulokset!$I$56="",'1'!$I$57="",'1'!$K$57=""),"",IF(SIGN('1'!$I$57-'1'!$K$57)<>SIGN(Tulokset!$G$56-Tulokset!$I$56),0,IF(Tulokset!$G$56=Tulokset!$I$56,IF(AND('1'!$I$57=Tulokset!$G$56,'1'!$K$57=Tulokset!$I$56),6,3),MAX(0,6-(ABS('1'!$I$57-Tulokset!$G$56)+ABS('1'!$K$57-Tulokset!$I$56)))))) | BG4: =IF(OR(Tulokset!$G$57="",Tulokset!$I$57="",'1'!$I$58="",'1'!$K$58=""),"",IF(SIGN('1'!$I$58-'1'!$K$58)<>SIGN(Tulokset!$G$57-Tulokset!$I$57),0,IF(Tulokset!$G$57=Tulokset!$I$57,IF(AND('1'!$I$58=Tulokset!$G$57,'1'!$K$58=Tulokset!$I$57),6,3),MAX(0,6-(ABS('1'!$I$58-Tulokset!$G$57)+ABS('1'!$K$58-Tulokset!$I$57)))))) | BH4: =IF(OR(Tulokset!$G$58="",Tulokset!$I$58="",'1'!$I$59="",'1'!$K$59=""),"",IF(SIGN('1'!$I$59-'1'!$K$59)<>SIGN(Tulokset!$G$58-Tulokset!$I$58),0,IF(Tulokset!$G$58=Tulokset!$I$58,IF(AND('1'!$I$59=Tulokset!$G$58,'1'!$K$59=Tulokset!$I$58),6,3),MAX(0,6-(ABS('1'!$I$59-Tulokset!$G$58)+ABS('1'!$K$59-Tulokset!$I$58)))))) | BI4: =IF(OR(Tulokset!$G$59="",Tulokset!$I$59="",'1'!$I$60="",'1'!$K$60=""),"",IF(SIGN('1'!$I$60-'1'!$K$60)<>SIGN(Tulokset!$G$59-Tulokset!$I$59),0,IF(Tulokset!$G$59=Tulokset!$I$59,IF(AND('1'!$I$60=Tulokset!$G$59,'1'!$K$60=Tulokset!$I$59),6,3),MAX(0,6-(ABS('1'!$I$60-Tulokset!$G$59)+ABS('1'!$K$60-Tulokset!$I$59)))))) | BJ4: =IF(OR(Tulokset!$G$60="",Tulokset!$I$60="",'1'!$I$61="",'1'!$K$61=""),"",IF(SIGN('1'!$I$61-'1'!$K$61)<>SIGN(Tulokset!$G$60-Tulokset!$I$60),0,IF(Tulokset!$G$60=Tulokset!$I$60,IF(AND('1'!$I$61=Tulokset!$G$60,'1'!$K$61=Tulokset!$I$60),6,3),MAX(0,6-(ABS('1'!$I$61-Tulokset!$G$60)+ABS('1'!$K$61-Tulokset!$I$60)))))) | BK4: =IF(OR(Tulokset!$G$61="",Tulokset!$I$61="",'1'!$I$62="",'1'!$K$62=""),"",IF(SIGN('1'!$I$62-'1'!$K$62)<>SIGN(Tulokset!$G$61-Tulokset!$I$61),0,IF(Tulokset!$G$61=Tulokset!$I$61,IF(AND('1'!$I$62=Tulokset!$G$61,'1'!$K$62=Tulokset!$I$61),6,3),MAX(0,6-(ABS('1'!$I$62-Tulokset!$G$61)+ABS('1'!$K$62-Tulokset!$I$61)))))) | BL4: =IF(OR(Tulokset!$G$62="",Tulokset!$I$62="",'1'!$I$63="",'1'!$K$63=""),"",IF(SIGN('1'!$I$63-'1'!$K$63)<>SIGN(Tulokset!$G$62-Tulokset!$I$62),0,IF(Tulokset!$G$62=Tulokset!$I$62,IF(AND('1'!$I$63=Tulokset!$G$62,'1'!$K$63=Tulokset!$I$62),6,3),MAX(0,6-(ABS('1'!$I$63-Tulokset!$G$62)+ABS('1'!$K$63-Tulokset!$I$62)))))) | BM4: =IF(OR(Tulokset!$G$63="",Tulokset!$I$63="",'1'!$I$64="",'1'!$K$64=""),"",IF(SIGN('1'!$I$64-'1'!$K$64)<>SIGN(Tulokset!$G$63-Tulokset!$I$63),0,IF(Tulokset!$G$63=Tulokset!$I$63,IF(AND('1'!$I$64=Tulokset!$G$63,'1'!$K$64=Tulokset!$I$63),6,3),MAX(0,6-(ABS('1'!$I$64-Tulokset!$G$63)+ABS('1'!$K$64-Tulokset!$I$63)))))) | BN4: =IF(OR(Tulokset!$G$64="",Tulokset!$I$64="",'1'!$I$65="",'1'!$K$65=""),"",IF(SIGN('1'!$I$65-'1'!$K$65)<>SIGN(Tulokset!$G$64-Tulokset!$I$64),0,IF(Tulokset!$G$64=Tulokset!$I$64,IF(AND('1'!$I$65=Tulokset!$G$64,'1'!$K$65=Tulokset!$I$64),6,3),MAX(0,6-(ABS('1'!$I$65-Tulokset!$G$64)+ABS('1'!$K$65-Tulokset!$I$64)))))) | BO4: =IF(OR(Tulokset!$G$65="",Tulokset!$I$65="",'1'!$I$66="",'1'!$K$66=""),"",IF(SIGN('1'!$I$66-'1'!$K$66)<>SIGN(Tulokset!$G$65-Tulokset!$I$65),0,IF(Tulokset!$G$65=Tulokset!$I$65,IF(AND('1'!$I$66=Tulokset!$G$65,'1'!$K$66=Tulokset!$I$65),6,3),MAX(0,6-(ABS('1'!$I$66-Tulokset!$G$65)+ABS('1'!$K$66-Tulokset!$I$65)))))) | BP4: =IF(OR(Tulokset!$G$66="",Tulokset!$I$66="",'1'!$I$67="",'1'!$K$67=""),"",IF(SIGN('1'!$I$67-'1'!$K$67)<>SIGN(Tulokset!$G$66-Tulokset!$I$66),0,IF(Tulokset!$G$66=Tulokset!$I$66,IF(AND('1'!$I$67=Tulokset!$G$66,'1'!$K$67=Tulokset!$I$66),6,3),MAX(0,6-(ABS('1'!$I$67-Tulokset!$G$66)+ABS('1'!$K$67-Tulokset!$I$66)))))) | BQ4: =IF(OR(Tulokset!$G$67="",Tulokset!$I$67="",'1'!$I$68="",'1'!$K$68=""),"",IF(SIGN('1'!$I$68-'1'!$K$68)<>SIGN(Tulokset!$G$67-Tulokset!$I$67),0,IF(Tulokset!$G$67=Tulokset!$I$67,IF(AND('1'!$I$68=Tulokset!$G$67,'1'!$K$68=Tulokset!$I$67),6,3),MAX(0,6-(ABS('1'!$I$68-Tulokset!$G$67)+ABS('1'!$K$68-Tulokset!$I$67)))))) | BR4: =IF(OR(Tulokset!$G$68="",Tulokset!$I$68="",'1'!$I$69="",'1'!$K$69=""),"",IF(SIGN('1'!$I$69-'1'!$K$69)<>SIGN(Tulokset!$G$68-Tulokset!$I$68),0,IF(Tulokset!$G$68=Tulokset!$I$68,IF(AND('1'!$I$69=Tulokset!$G$68,'1'!$K$69=Tulokset!$I$68),6,3),MAX(0,6-(ABS('1'!$I$69-Tulokset!$G$68)+ABS('1'!$K$69-Tulokset!$I$68)))))) | BS4: =IF(OR(Tulokset!$G$69="",Tulokset!$I$69="",'1'!$I$70="",'1'!$K$70=""),"",IF(SIGN('1'!$I$70-'1'!$K$70)<>SIGN(Tulokset!$G$69-Tulokset!$I$69),0,IF(Tulokset!$G$69=Tulokset!$I$69,IF(AND('1'!$I$70=Tulokset!$G$69,'1'!$K$70=Tulokset!$I$69),6,3),MAX(0,6-(ABS('1'!$I$70-Tulokset!$G$69)+ABS('1'!$K$70-Tulokset!$I$69)))))) | BT4: =IF(OR(Tulokset!$G$70="",Tulokset!$I$70="",'1'!$I$71="",'1'!$K$71=""),"",IF(SIGN('1'!$I$71-'1'!$K$71)<>SIGN(Tulokset!$G$70-Tulokset!$I$70),0,IF(Tulokset!$G$70=Tulokset!$I$70,IF(AND('1'!$I$71=Tulokset!$G$70,'1'!$K$71=Tulokset!$I$70),6,3),MAX(0,6-(ABS('1'!$I$71-Tulokset!$G$70)+ABS('1'!$K$71-Tulokset!$I$70)))))) | BU4: =IF(OR(Tulokset!$G$71="",Tulokset!$I$71="",'1'!$I$72="",'1'!$K$72=""),"",IF(SIGN('1'!$I$72-'1'!$K$72)<>SIGN(Tulokset!$G$71-Tulokset!$I$71),0,IF(Tulokset!$G$71=Tulokset!$I$71,IF(AND('1'!$I$72=Tulokset!$G$71,'1'!$K$72=Tulokset!$I$71),6,3),MAX(0,6-(ABS('1'!$I$72-Tulokset!$G$71)+ABS('1'!$K$72-Tulokset!$I$71)))))) | BV4: =IF(OR(Tulokset!$G$72="",Tulokset!$I$72="",'1'!$I$73="",'1'!$K$73=""),"",IF(SIGN('1'!$I$73-'1'!$K$73)<>SIGN(Tulokset!$G$72-Tulokset!$I$72),0,IF(Tulokset!$G$72=Tulokset!$I$72,IF(AND('1'!$I$73=Tulokset!$G$72,'1'!$K$73=Tulokset!$I$72),6,3),MAX(0,6-(ABS('1'!$I$73-Tulokset!$G$72)+ABS('1'!$K$73-Tulokset!$I$72)))))) | BW4: =IF(OR(Tulokset!$G$73="",Tulokset!$I$73="",'1'!$I$74="",'1'!$K$74=""),"",IF(SIGN('1'!$I$74-'1'!$K$74)<>SIGN(Tulokset!$G$73-Tulokset!$I$73),0,IF(Tulokset!$G$73=Tulokset!$I$73,IF(AND('1'!$I$74=Tulokset!$G$73,'1'!$K$74=Tulokset!$I$73),6,3),MAX(0,6-(ABS('1'!$I$74-Tulokset!$G$73)+ABS('1'!$K$74-Tulokset!$I$73)))))) | BX4: =IF(OR(Tulokset!$G$74="",Tulokset!$I$74="",'1'!$I$75="",'1'!$K$75=""),"",IF(SIGN('1'!$I$75-'1'!$K$75)<>SIGN(Tulokset!$G$74-Tulokset!$I$74),0,IF(Tulokset!$G$74=Tulokset!$I$74,IF(AND('1'!$I$75=Tulokset!$G$74,'1'!$K$75=Tulokset!$I$74),6,3),MAX(0,6-(ABS('1'!$I$75-Tulokset!$G$74)+ABS('1'!$K$75-Tulokset!$I$74)))))) | BY4: =IF(OR(Tulokset!$G$75="",Tulokset!$I$75="",'1'!$I$76="",'1'!$K$76=""),"",IF(SIGN('1'!$I$76-'1'!$K$76)<>SIGN(Tulokset!$G$75-Tulokset!$I$75),0,IF(Tulokset!$G$75=Tulokset!$I$75,IF(AND('1'!$I$76=Tulokset!$G$75,'1'!$K$76=Tulokset!$I$75),6,3),MAX(0,6-(ABS('1'!$I$76-Tulokset!$G$75)+ABS('1'!$K$76-Tulokset!$I$75)))))) | BZ4: =IF(OR(Tulokset!$G$76="",Tulokset!$I$76="",'1'!$I$77="",'1'!$K$77=""),"",IF(SIGN('1'!$I$77-'1'!$K$77)<>SIGN(Tulokset!$G$76-Tulokset!$I$76),0,IF(Tulokset!$G$76=Tulokset!$I$76,IF(AND('1'!$I$77=Tulokset!$G$76,'1'!$K$77=Tulokset!$I$76),6,3),MAX(0,6-(ABS('1'!$I$77-Tulokset!$G$76)+ABS('1'!$K$77-Tulokset!$I$76)))))) | CA4: =IF(OR(Tulokset!$G$77="",Tulokset!$I$77="",'1'!$I$78="",'1'!$K$78=""),"",IF(SIGN('1'!$I$78-'1'!$K$78)<>SIGN(Tulokset!$G$77-Tulokset!$I$77),0,IF(Tulokset!$G$77=Tulokset!$I$77,IF(AND('1'!$I$78=Tulokset!$G$77,'1'!$K$78=Tulokset!$I$77),6,3),MAX(0,6-(ABS('1'!$I$78-Tulokset!$G$77)+ABS('1'!$K$78-Tulokset!$I$77)))))) | CD4: =IF(OR(Tulokset!$M$6="",INDIRECT("'"&$A4&"'!$P$8")=""),"",IF(TRIM(INDIRECT("'"&$A4&"'!$P$8"))=TRIM(Tulokset!$M$6),2,0)) | CE4: =IF(OR(Tulokset!$M$7="",INDIRECT("'"&$A4&"'!$P$9")=""),"",IF(TRIM(INDIRECT("'"&$A4&"'!$P$9"))=TRIM(Tulokset!$M$7),2,0)) | CF4: =IF(OR(Tulokset!$M$8="",INDIRECT("'"&$A4&"'!$P$10")=""),"",IF(TRIM(INDIRECT("'"&$A4&"'!$P$10"))=TRIM(Tulokset!$M$8),2,0)) | CG4: =IF(OR(Tulokset!$M$9="",INDIRECT("'"&$A4&"'!$P$11")=""),"",IF(TRIM(INDIRECT("'"&$A4&"'!$P$11"))=TRIM(Tulokset!$M$9),2,0)) | CH4: =IF(OR(Tulokset!$N$6="",INDIRECT("'"&$A4&"'!$Q$8")=""),"",IF(TRIM(INDIRECT("'"&$A4&"'!$Q$8"))=TRIM(Tulokset!$N$6),2,0)) | CI4: =IF(OR(Tulokset!$N$7="",INDIRECT("'"&$A4&"'!$Q$9")=""),"",IF(TRIM(INDIRECT("'"&$A4&"'!$Q$9"))=TRIM(Tulokset!$N$7),2,0)) | CJ4: =IF(OR(Tulokset!$N$8="",INDIRECT("'"&$A4&"'!$Q$10")=""),"",IF(TRIM(INDIRECT("'"&$A4&"'!$Q$10"))=TRIM(Tulokset!$N$8),2,0)) | CK4: =IF(OR(Tulokset!$N$9="",INDIRECT("'"&$A4&"'!$Q$11")=""),"",IF(TRIM(INDIRECT("'"&$A4&"'!$Q$11"))=TRIM(Tulokset!$N$9),2,0)) | CL4: =IF(OR(Tulokset!$O$6="",INDIRECT("'"&$A4&"'!$R$8")=""),"",IF(TRIM(INDIRECT("'"&$A4&"'!$R$8"))=TRIM(Tulokset!$O$6),2,0)) | CM4: =IF(OR(Tulokset!$O$7="",INDIRECT("'"&$A4&"'!$R$9")=""),"",IF(TRIM(INDIRECT("'"&$A4&"'!$R$9"))=TRIM(Tulokset!$O$7),2,0)) | CN4: =IF(OR(Tulokset!$O$8="",INDIRECT("'"&$A4&"'!$R$10")=""),"",IF(TRIM(INDIRECT("'"&$A4&"'!$R$10"))=TRIM(Tulokset!$O$8),2,0)) | CO4: =IF(OR(Tulokset!$O$9="",INDIRECT("'"&$A4&"'!$R$11")=""),"",IF(TRIM(INDIRECT("'"&$A4&"'!$R$11"))=TRIM(Tulokset!$O$9),2,0)) | CP4: =IF(OR(Tulokset!$P$6="",INDIRECT("'"&$A4&"'!$S$8")=""),"",IF(TRIM(INDIRECT("'"&$A4&"'!$S$8"))=TRIM(Tulokset!$P$6),2,0)) | CQ4: =IF(OR(Tulokset!$P$7="",INDIRECT("'"&$A4&"'!$S$9")=""),"",IF(TRIM(INDIRECT("'"&$A4&"'!$S$9"))=TRIM(Tulokset!$P$7),2,0)) | CR4: =IF(OR(Tulokset!$P$8="",INDIRECT("'"&$A4&"'!$S$10")=""),"",IF(TRIM(INDIRECT("'"&$A4&"'!$S$10"))=TRIM(Tulokset!$P$8),2,0)) | CS4: =IF(OR(Tulokset!$P$9="",INDIRECT("'"&$A4&"'!$S$11")=""),"",IF(TRIM(INDIRECT("'"&$A4&"'!$S$11"))=TRIM(Tulokset!$P$9),2,0)) | CT4: =IF(OR(Tulokset!$Q$6="",INDIRECT("'"&$A4&"'!$T$8")=""),"",IF(TRIM(INDIRECT("'"&$A4&"'!$T$8"))=TRIM(Tulokset!$Q$6),2,0)) | CU4: =IF(OR(Tulokset!$Q$7="",INDIRECT("'"&$A4&"'!$T$9")=""),"",IF(TRIM(INDIRECT("'"&$A4&"'!$T$9"))=TRIM(Tulokset!$Q$7),2,0)) | CV4: =IF(OR(Tulokset!$Q$8="",INDIRECT("'"&$A4&"'!$T$10")=""),"",IF(TRIM(INDIRECT("'"&$A4&"'!$T$10"))=TRIM(Tulokset!$Q$8),2,0)) | CW4: =IF(OR(Tulokset!$Q$9="",INDIRECT("'"&$A4&"'!$T$11")=""),"",IF(TRIM(INDIRECT("'"&$A4&"'!$T$11"))=TRIM(Tulokset!$Q$9),2,0)) | CX4: =IF(OR(Tulokset!$R$6="",INDIRECT("'"&$A4&"'!$U$8")=""),"",IF(TRIM(INDIRECT("'"&$A4&"'!$U$8"))=TRIM(Tulokset!$R$6),2,0)) | CY4: =IF(OR(Tulokset!$R$7="",INDIRECT("'"&$A4&"'!$U$9")=""),"",IF(TRIM(INDIRECT("'"&$A4&"'!$U$9"))=TRIM(Tulokset!$R$7),2,0)) | CZ4: =IF(OR(Tulokset!$R$8="",INDIRECT("'"&$A4&"'!$U$10")=""),"",IF(TRIM(INDIRECT("'"&$A4&"'!$U$10"))=TRIM(Tulokset!$R$8),2,0)) | DA4: =IF(OR(Tulokset!$R$9="",INDIRECT("'"&$A4&"'!$U$11")=""),"",IF(TRIM(INDIRECT("'"&$A4&"'!$U$11"))=TRIM(Tulokset!$R$9),2,0)) | DB4: =IF(OR(Tulokset!$M$12="",INDIRECT("'"&$A4&"'!$P$14")=""),"",IF(TRIM(INDIRECT("'"&$A4&"'!$P$14"))=TRIM(Tulokset!$M$12),2,0)) | DC4: =IF(OR(Tulokset!$M$13="",INDIRECT("'"&$A4&"'!$P$15")=""),"",IF(TRIM(INDIRECT("'"&$A4&"'!$P$15"))=TRIM(Tulokset!$M$13),2,0)) | DD4: =IF(OR(Tulokset!$M$14="",INDIRECT("'"&$A4&"'!$P$16")=""),"",IF(TRIM(INDIRECT("'"&$A4&"'!$P$16"))=TRIM(Tulokset!$M$14),2,0)) | DE4: =IF(OR(Tulokset!$M$15="",INDIRECT("'"&$A4&"'!$P$17")=""),"",IF(TRIM(INDIRECT("'"&$A4&"'!$P$17"))=TRIM(Tulokset!$M$15),2,0)) | DF4: =IF(OR(Tulokset!$N$12="",INDIRECT("'"&$A4&"'!$Q$14")=""),"",IF(TRIM(INDIRECT("'"&$A4&"'!$Q$14"))=TRIM(Tulokset!$N$12),2,0)) | DG4: =IF(OR(Tulokset!$N$13="",INDIRECT("'"&$A4&"'!$Q$15")=""),"",IF(TRIM(INDIRECT("'"&$A4&"'!$Q$15"))=TRIM(Tulokset!$N$13),2,0)) | DH4: =IF(OR(Tulokset!$N$14="",INDIRECT("'"&$A4&"'!$Q$16")=""),"",IF(TRIM(INDIRECT("'"&$A4&"'!$Q$16"))=TRIM(Tulokset!$N$14),2,0)) | DI4: =IF(OR(Tulokset!$N$15="",INDIRECT("'"&$A4&"'!$Q$17")=""),"",IF(TRIM(INDIRECT("'"&$A4&"'!$Q$17"))=TRIM(Tulokset!$N$15),2,0)) | DJ4: =IF(OR(Tulokset!$O$12="",INDIRECT("'"&$A4&"'!$R$14")=""),"",IF(TRIM(INDIRECT("'"&$A4&"'!$R$14"))=TRIM(Tulokset!$O$12),2,0)) | DK4: =IF(OR(Tulokset!$O$13="",INDIRECT("'"&$A4&"'!$R$15")=""),"",IF(TRIM(INDIRECT("'"&$A4&"'!$R$15"))=TRIM(Tulokset!$O$13),2,0)) | DL4: =IF(OR(Tulokset!$O$14="",INDIRECT("'"&$A4&"'!$R$16")=""),"",IF(TRIM(INDIRECT("'"&$A4&"'!$R$16"))=TRIM(Tulokset!$O$14),2,0)) | DM4: =IF(OR(Tulokset!$O$15="",INDIRECT("'"&$A4&"'!$R$17")=""),"",IF(TRIM(INDIRECT("'"&$A4&"'!$R$17"))=TRIM(Tulokset!$O$15),2,0)) | DN4: =IF(OR(Tulokset!$P$12="",INDIRECT("'"&$A4&"'!$S$14")=""),"",IF(TRIM(INDIRECT("'"&$A4&"'!$S$14"))=TRIM(Tulokset!$P$12),2,0)) | DO4: =IF(OR(Tulokset!$P$13="",INDIRECT("'"&$A4&"'!$S$15")=""),"",IF(TRIM(INDIRECT("'"&$A4&"'!$S$15"))=TRIM(Tulokset!$P$13),2,0)) | DP4: =IF(OR(Tulokset!$P$14="",INDIRECT("'"&$A4&"'!$S$16")=""),"",IF(TRIM(INDIRECT("'"&$A4&"'!$S$16"))=TRIM(Tulokset!$P$14),2,0)) | DQ4: =IF(OR(Tulokset!$P$15="",INDIRECT("'"&$A4&"'!$S$17")=""),"",IF(TRIM(INDIRECT("'"&$A4&"'!$S$17"))=TRIM(Tulokset!$P$15),2,0)) | DR4: =IF(OR(Tulokset!$Q$12="",INDIRECT("'"&$A4&"'!$T$14")=""),"",IF(TRIM(INDIRECT("'"&$A4&"'!$T$14"))=TRIM(Tulokset!$Q$12),2,0)) | DS4: =IF(OR(Tulokset!$Q$13="",INDIRECT("'"&$A4&"'!$T$15")=""),"",IF(TRIM(INDIRECT("'"&$A4&"'!$T$15"))=TRIM(Tulokset!$Q$13),2,0)) | DT4: =IF(OR(Tulokset!$Q$14="",INDIRECT("'"&$A4&"'!$T$16")=""),"",IF(TRIM(INDIRECT("'"&$A4&"'!$T$16"))=TRIM(Tulokset!$Q$14),2,0)) | DU4: =IF(OR(Tulokset!$Q$15="",INDIRECT("'"&$A4&"'!$T$17")=""),"",IF(TRIM(INDIRECT("'"&$A4&"'!$T$17"))=TRIM(Tulokset!$Q$15),2,0)) | DV4: =IF(OR(Tulokset!$R$12="",INDIRECT("'"&$A4&"'!$U$14")=""),"",IF(TRIM(INDIRECT("'"&$A4&"'!$U$14"))=TRIM(Tulokset!$R$12),2,0)) | DW4: =IF(OR(Tulokset!$R$13="",INDIRECT("'"&$A4&"'!$U$15")=""),"",IF(TRIM(INDIRECT("'"&$A4&"'!$U$15"))=TRIM(Tulokset!$R$13),2,0)) | DX4: =IF(OR(Tulokset!$R$14="",INDIRECT("'"&$A4&"'!$U$16")=""),"",IF(TRIM(INDIRECT("'"&$A4&"'!$U$16"))=TRIM(Tulokset!$R$14),2,0)) | DY4: =IF(OR(Tulokset!$R$15="",INDIRECT("'"&$A4&"'!$U$17")=""),"",IF(TRIM(INDIRECT("'"&$A4&"'!$U$17"))=TRIM(Tulokset!$R$15),2,0)) | EA4: =IF(OR(INDIRECT("'"&$A4&"'!$E$79")="",COUNTA(Tulokset!$M$20:$M$21)=0),"",IF(COUNTIF(Tulokset!$M$20:$M$21,INDIRECT("'"&$A4&"'!$E$79"))>0,2,0)) | EB4: =IF(OR(INDIRECT("'"&$A4&"'!$G$79")="",COUNTA(Tulokset!$M$20:$M$21)=0),"",IF(COUNTIF(Tulokset!$M$20:$M$21,INDIRECT("'"&$A4&"'!$G$79"))>0,2,0)) | EC4: =IF(OR(INDIRECT("'"&$A4&"'!$E$80")="",COUNTA(Tulokset!$M$23:$M$24)=0),"",IF(COUNTIF(Tulokset!$M$23:$M$24,INDIRECT("'"&$A4&"'!$E$80"))>0,2,0)) | ED4: =IF(OR(INDIRECT("'"&$A4&"'!$G$80")="",COUNTA(Tulokset!$M$23:$M$24)=0),"",IF(COUNTIF(Tulokset!$M$23:$M$24,INDIRECT("'"&$A4&"'!$G$80"))>0,2,0))
